Traceback (most recent call last):
  File "/Users/nikhilanand/airflow_venv/lib/python3.9/site-packages/lockfile/pidlockfile.py", line 77, in acquire
    write_pid_to_pidfile(self.path)
  File "/Users/nikhilanand/airflow_venv/lib/python3.9/site-packages/lockfile/pidlockfile.py", line 161, in write_pid_to_pidfile
    pidfile_fd = os.open(pidfile_path, open_flags, open_mode)
FileExistsError: [Errno 17] File exists: '/Users/nikhilanand/airflow/airflow-scheduler.pid'

During handling of the above exception, another exception occurred:

Traceback (most recent call last):
  File "/Users/nikhilanand/airflow_venv/bin/airflow", line 8, in <module>
    sys.exit(main())
  File "/Users/nikhilanand/airflow_venv/lib/python3.9/site-packages/airflow/__main__.py", line 48, in main
    args.func(args)
  File "/Users/nikhilanand/airflow_venv/lib/python3.9/site-packages/airflow/cli/cli_parsTraceback (most recent call last):
  File "/Users/nikhilanand/airflow_venv/bin/airflow", line 8, in <module>
    sys.exit(main())
  File "/Users/nikhilanand/airflow_venv/lib/python3.9/site-packages/airflow/__main__.py", line 48, in main
    args.func(args)
  File "/Users/nikhilanand/airflow_venv/lib/python3.9/site-packages/airflow/cli/cli_parser.py", line 48, in command
    return func(*args, **kwargs)
  File "/Users/nikhilanand/airflow_venv/lib/python3.9/site-packages/airflow/utils/cli.py", line 92, in wrapper
    return f(*args, **kwargs)
  File "/Users/nikhilanand/airflow_venv/lib/python3.9/site-packages/airflow/cli/commands/scheduler_command.py", line 70, in scheduler
    _run_scheduler_job(args=args)
  File "/Users/nikhilanand/airflow_venv/lib/python3.9/site-packages/airflow/cli/commands/scheduler_command.py", line 46, in _run_scheduler_job
    job.run()
  File "/Users/nikhilanand/airflow_venv/lib/python3.9/site-packages/airflow/jobs/base_job.py", line 245, in run
    self._execute()
  File "/Users/nikhilanand/airflow_venv/lib/python3.9/site-packages/airflow/jobs/scheduler_job.py", line 628, in _execute
    self._run_scheduler_loop()
  File "/Users/nikhilanand/airflow_venv/lib/python3.9/site-packages/airflow/jobs/scheduler_job.py", line 709, in _run_scheduler_loop
    num_queued_tis = self._do_scheduling(session)
  File "/Users/nikhilanand/airflow_venv/lib/python3.9/site-packages/airflow/jobs/scheduler_job.py", line 782, in _do_scheduling
    self._create_dagruns_for_dags(guard, session)
  File "/Users/nikhilanand/airflow_venv/lib/python3.9/site-packages/airflow/utils/retries.py", line 76, in wrapped_function
    for attempt in run_with_db_retries(max_retries=retries, logger=logger, **retry_kwargs):
  File "/Users/nikhilanand/airflow_venv/lib/python3.9/site-packages/tenacity/__init__.py", line 382, in __iter__
    do = self.iter(retry_state=retry_state)
  File "/Users/nikhilanand/airflow_venv/lib/python3.9/site-packages/tenacity/__init__.py", line 349, in iter
    return fut.result()
  File "/Users/nikhilanand/opt/anaconda3/lib/python3.9/concurrent/futures/_base.py", line 439, in result
    return self.__get_result()
  File "/Users/nikhilanand/opt/anaconda3/lib/python3.9/concurrent/futures/_base.py", line 391, in __get_result
    raise self._exception
  File "/Users/nikhilanand/airflow_venv/lib/python3.9/site-packages/airflow/utils/retries.py", line 85, in wrapped_function
    return func(*args, **kwargs)
  File "/Users/nikhilanand/airflow_venv/lib/python3.9/site-packages/airflow/jobs/scheduler_job.py", line 847, in _create_dagruns_for_dags
    self._create_dag_runs(query.all(), session)
  File "/Users/nikhilanand/airflow_venv/lib/python3.9/site-packages/sqlalchemy/orm/query.py", line 3373, in all
    return list(self)
  File "/Users/nikhilanand/airflow_venv/lib/python3.9/site-packages/sqlalchemy/orm/query.py", line 3535, in __iter__
    return self._execute_and_instances(context)
  File "/Users/nikhilanand/airflow_venv/lib/python3.9/site-packages/sqlalchemy/orm/query.py", line 3556, in _execute_and_instances
    conn = self._get_bind_args(
  File "/Users/nikhilanand/airflow_venv/lib/python3.9/site-packages/sqlalchemy/orm/query.py", line 3571, in _get_bind_args
    return fn(
  File "/Users/nikhilanand/airflow_venv/lib/python3.9/site-packages/sqlalchemy/orm/query.py", line 3550, in _connection_from_session
    conn = self.session.connection(**kw)
  File "/Users/nikhilanand/airflow_venv/lib/python3.9/site-packages/sqlalchemy/orm/session.py", line 1142, in connection
    return self._connection_for_bind(
  File "/Users/nikhilanand/airflow_venv/lib/python3.9/site-packages/sqlalchemy/orm/session.py", line 1150, in _connection_for_bind
    return self.transaction._connection_for_bind(
  File "/Users/nikhilanand/airflow_venv/lib/python3.9/site-packages/sqlalchemy/orm/session.py", line 409, in _connection_for_bind
    self._assert_active()
  File "/Users/nikhilanand/airflow_venv/lib/python3.9/site-packages/sqlalchemy/orm/session.py", line 289, in _assert_active
    raise sa_exc.InvalidRequestError(
sqlalchemy.exc.InvalidRequestError: This Session's transaction has been rolled back due to a previous exception during flush. To begin a new transaction with this Session, first issue Session.rollback(). Original exception was: (sqlite3.IntegrityError) UNIQUE constraint failed: dag_run.dag_id, dag_run.run_id
[SQL: INSERT INTO dag_run (dag_id, queued_at, execution_date, start_date, end_date, state, run_id, creating_job_id, external_trigger, run_type, conf, data_interval_start, data_interval_end, last_scheduling_decision, dag_hash) VALUES (?, ?, ?, ?, ?, ?, ?, ?, ?, ?, ?, ?, ?, ?, ?)]
[parameters: ('hello_world_dag', '2024-03-01 16:55:01.146753', '2024-03-01 16:54:00.000000', None, None, <TaskInstanceState.QUEUED: 'queued'>, 'scheduled__2024-03-01T16:54:00+00:00', 6, 0, <DagRunType.SCHEDULED: 'scheduled'>, <memory at 0x7f9c104e1700>, '2024-03-01 16:54:00.000000', '2024-03-01 16:55:00.000000', None, '35ff92905300329940d9a770452e13fe')]
(Background on this error at: http://sqlalche.me/e/13/gkpj) (Background on this error at: http://sqlalche.me/e/13/7s2a)
